Workbook

Sheet Planilha4
A1: MÉDIA | B1: (Tudo)
A3: Rótulos de Linha | B3: Soma de GERAL | C3: Soma de MÉDIA
A4: 01. Block Busters | B4: 224 | C4: 24.888889
A5: Arikleyton | B5: 78 | C5: 8.6666667
A6: Lennon | B6: 65 | C6: 7.2222222
A7: Manoel | B7: 81 | C7: 9
A8: 02. Apenas Uma Porta | B8: 140 | C8: 15.555556
A9: Arikleyton | B9: 70 | C9: 7.7777778
A10: Manoel | B10: 70 | C10: 7.7777778
A11: 03. Just One More Time | B11: 141 | C11: 15.666667
A12: Arikleyton | B12: 74 | C12: 8.2222222
A13: Lennon | B13: 67 | C13: 7.4444444
A14: 04. Captus Gator | B14: 224 | C14: 24.888889
A15: Arikleyton | B15: 77 | C15: 8.5555556
... A81: Total Geral | B81: 3844 | C81: 427.11111

Sheet Planilha5
A1: Rótulos de Linha | B1: Soma de GERAL | C1: Soma de MÉDIA
A2: 21. Spear rush | B2: 245 | C2: 27.222222
A3: 17. Paragominas: One Mission | B3: 243 | C3: 27
A4: 12. Singular | B4: 239 | C4: 26.555556
A5: 20. O culpado entre nós | B5: 227 | C5: 25.222222
A6: 04. Captus Gator | B6: 224 | C6: 24.888889
A7: 01. Block Busters | B7: 224 | C7: 24.888889
A8: 11. The Apotheosis of Ivy | B8: 216 | C8: 24
A9: 19. ORFEU | B9: 216 | C9: 24
A10: 14. INFragmentado | B10: 215 | C10: 23.888889
A11: 08. BLACK FOREST | B11: 215 | C11: 23.888889
A12: 22. Tiny Sword | B12: 202 | C12: 22.444444
A13: 05. Apenas Um Passo | B13: 189 | C13: 21
... A23: 15. Apenas um | B23: 45 | C23: 5

Sheet Respostas ao formulário 1
A1: Carimbo de data/hora | B1: ? | C1: Nome do Jogo | D1: Adequação ao Tema | E1: Originalidade e Criatividade | F1: Diversão e Engajamento | G1: Mecânicas e Controles | H1: Estética e Design Gráfico | I1: Áudio (Música e Efeitos) | J1: Estabilidade | K1: Completude | L1: POTENCIAL DE VENCEDOR | M1: MÉDIA | N1: GERAL | O1: Comentários sobre sua experiencia testando
A2: 46290.631 | B2: Arikleyton | C2: 01. Block Busters | D2: 9 | E2: 7 | F2: 9 | G2: 9 | H2: 8 | I2: 8 | J2: 10 | K2: 10 | L2: 8 | M2: =AVERAGE(Form_Responses[[#This Row],[Adequação ao Tema]:[POTENCIAL DE VENCEDOR]]) -> 8.6666667 | N2: =SUM(Form_Responses[[#This Row],[Adequação ao Tema]:[POTENCIAL DE VENCEDOR]]) -> 78 | O2: Botão de desligar som não funciona, arte bonita, mas não inova.
A3: 46290.633 | B3: Arikleyton | C3: 02. Apenas Uma Porta | D3: 9 | E3: 7 | F3: 6 | G3: 8 | H3: 7 | I3: 8 | J3: 10 | K3: 10 | L3: 5 | M3: =AVERAGE(Form_Responses[[#This Row],[Adequação ao Tema]:[POTENCIAL DE VENCEDOR]]) -> 7.7777778 | N3: =SUM(Form_Responses[[#This Row],[Adequação ao Tema]:[POTENCIAL DE VENCEDOR]]) -> 70 | O3: Mecânica simples e repetitiva. As perguntas não variam, apresentando pouca dificuldade.
A4: 46290.639 | B4: Arikleyton | C4: 03. Just One More Time | D4: 8 | E4: 7 | F4: 6 | G4: 8 | H4: 9 | I4: 9 | J4: 10 | K4: 9 | L4: 8 | M4: =AVERAGE(Form_Responses[[#This Row],[Adequação ao Tema]:[POTENCIAL DE VENCEDOR]]) -> 8.2222222 | N4: =SUM(Form_Responses[[#This Row],[Adequação ao Tema]:[POTENCIAL DE VENCEDOR]]) -> 74 | O4: Algumas mecânicas não estão bem polidas e o nível de dificuldade muda muito de uma fase para outra. Não sei se tem final pois não passei do mapa de gelo.
A5: 46290.645 | B5: Arikleyton | C5: 04. Captus Gator | D5: 9 | E5: 9 | F5: 8 | G5: 6 | H5: 9 | I5: 9 | J5: 10 | K5: 9 | L5: 8 | M5: =AVERAGE(Form_Responses[[#This Row],[Adequação ao Tema]:[POTENCIAL DE VENCEDOR]]) -> 8.5555556 | N5: =SUM(Form_Responses[[#This Row],[Adequação ao Tema]:[POTENCIAL DE VENCEDOR]]) -> 77 | O5: Vida do inimigo muito alta, o que gera uma dificuldade acentuada; Controle do tiro pouco flexivel.
A6: 46290.656 | B6: Arikleyton | C6: 05. Apenas Um Passo | D6: 8 | E6: 9 | F6: 8 | G6: 7 | H6: 8 | I6: 9 | J6: 10 | K6: 10 | L6: 8 | M6: =AVERAGE(Form_Responses[[#This Row],[Adequação ao Tema]:[POTENCIAL DE VENCEDOR]]) -> 8.5555556 | N6: =SUM(Form_Responses[[#This Row],[Adequação ao Tema]:[POTENCIAL DE VENCEDOR]]) -> 77 | O6: Tema forte, jogabilidade inteligente dentro da proposta, mas mecanicas pouco atrativas.
A7: 46290.66 | B7: Arikleyton | C7: 06. O último clique | D7: 7 | E7: 8 | F7: 6 | G7: 7 | H7: 6 | I7: 5 | J7: 9 | K7: 8 | L7: 5 | M7: =AVERAGE(Form_Responses[[#This Row],[Adequação ao Tema]:[POTENCIAL DE VENCEDOR]]) -> 6.7777778 | N7: =SUM(Form_Responses[[#This Row],[Adequação ao Tema]:[POTENCIAL DE VENCEDOR]]) -> 61 | O7: Controle confuso, mecanica da luz frustrante quando não se sabe o objetivo, dificuldade elevada para iniciantes.
A8: 46290.662 | B8: Arikleyton | C8: 07. Apenas uma luz | D8: 6 | E8: 6 | F8: 6 | G8: 8 | H8: 7 | I8: 9 | J8: 10 | K8: 10 | L8: 6 | M8: =AVERAGE(Form_Responses[[#This Row],[Adequação ao Tema]:[POTENCIAL DE VENCEDOR]]) -> 7.5555556 | N8: =SUM(Form_Responses[[#This Row],[Adequação ao Tema]:[POTENCIAL DE VENCEDOR]]) -> 68 | O8: COmeço intrigante, jogabilidade simples, mas pouco objetivos ou desafios. Nivel de dificuldade muito facil.
A9: 46290.669 | B9: Arikleyton | C9: 08. BLACK FOREST | D9: 6 | E9: 7 | F9: 7 | G9: 8 | H9: 8 | I9: 9 | J9: 10 | K9: 9 | L9: 6 | M9: =AVERAGE(Form_Responses[[#This Row],[Adequação ao Tema]:[POTENCIAL DE VENCEDOR]]) -> 7.7777778 | N9: =SUM(Form_Responses[[#This Row],[Adequação ao Tema]:[POTENCIAL DE VENCEDOR]]) -> 70 | O9: O jogo fica menos dificil quando guiado pelo minimapa. A coleta das paginas não é muito precisa. O tempo parece pouco para o desafio.
A10: 46290.678 | B10: Arikleyton | C10: 09. RESTA UM | D10: 6 | E10: 7 | F10: 7 | G10: 8 | H10: 6 | I10: 7 | J10: 9 | K10: 8 | L10: 6 | M10: =AVERAGE(Form_Responses[[#This Row],[Adequação ao Tema]:[POTENCIAL DE VENCEDOR]]) -> 7.1111111 | N10: =SUM(Form_Responses[[#This Row],[Adequação ao Tema]:[POTENCIAL DE VENCEDOR]]) -> 64 | O10: Escolhas nao mudam o resultado. O troca de controle entre os personagens é interessante mas nao acrescenta na narrativa.
A11: 46290.681 | B11: Arikleyton | C11: 10. A ÚLTIMA CHANCE | D11: 8 | E11: 6 | F11: 7 | G11: 9 | H11: 9 | I11: 9 | J11: 10 | K11: 10 | L11: 5 | M11: =AVERAGE(Form_Responses[[#This Row],[Adequação ao Tema]:[POTENCIAL DE VENCEDOR]]) -> 8.1111111 | N11: =SUM(Form_Responses[[#This Row],[Adequação ao Tema]:[POTENCIAL DE VENCEDOR]]) -> 73 | O11: jogo curto, com vitória centrada na aleatoriedade (sorte); arte e história ok, mas jogabilidade rasa.
A12: 46290.685 | B12: Arikleyton | C12: 11. The Apotheosis of Ivy | D12: 6 | E12: 7 | F12: 7 | G12: 7 | H12: 7 | I12: 9 | J12: 10 | K12: 9 | L12: 7 | M12: =AVERAGE(Form_Responses[[#This Row],[Adequação ao Tema]:[POTENCIAL DE VENCEDOR]]) -> 7.6666667 | N12: =SUM(Form_Responses[[#This Row],[Adequação ao Tema]:[POTENCIAL DE VENCEDOR]]) -> 69 | O12: Mecanica de recarregar confusa; narrativa pesada; tema forçado.
A13: 46290.692 | B13: Arikleyton | C13: 12. Singular | D13: 7 | E13: 7 | F13: 9 | G13: 10 | H13: 9 | I13: 9 | J13: 10 | K13: 10 | L13: 8 | M13: =AVERAGE(Form_Responses[[#This Row],[Adequação ao Tema]:[POTENCIAL DE VENCEDOR]]) -> 8.7777778 | N13: =SUM(Form_Responses[[#This Row],[Adequação ao Tema]:[POTENCIAL DE VENCEDOR]]) -> 79 | O13: Jogo completo, com dificuldade e jogabilidade agradável, mas tema forçado e sem inovação.
... A39: 46291.01 | B39: Manoel | C39: 22. Tiny Sword | D39: 9 | E39: 9 | F39: 9 | G39: 8 | H39: 9 | I39: 9 | J39: 8 | K39: 8 | L39: 8 | M39: =AVERAGE(Form_Responses[[#This Row],[Adequação ao Tema]:[POTENCIAL DE VENCEDOR]]) -> 8.5555556 | N39: =SUM(Form_Responses[[#This Row],[Adequação ao Tema]:[POTENCIAL DE VENCEDOR]]) -> 77 | O39: Já tinha visto, jogo legal, desafios interessantes gráficos bons, desenrola legal a medida em que joga-se. Cenários bem construído. A ideia das flechas e bombas foi interessante.
A40: 46291.338 | B40: Lennon | C40: 08. BLACK FOREST | D40: 8 | E40: 8 | F40: 8 | G40: 10 | H40: 10 | I40: 8 | J40: 10 | K40: 10 | L40: 7 | M40: =AVERAGE(Form_Responses[[#This Row],[Adequação ao Tema]:[POTENCIAL DE VENCEDOR]]) -> 8.7777778 | N40: =SUM(Form_Responses[[#This Row],[Adequação ao Tema]:[POTENCIAL DE VENCEDOR]]) -> 79
A41: 46291.342 | B41: Lennon | C41: 14. INFragmentado | D41: 7 | E41: 10 | F41: 8 | G41: 7 | H41: 10 | I41: 10 | J41: 10 | K41: 10 | L41: 7 | M41: =AVERAGE(Form_Responses[[#This Row],[Adequação ao Tema]:[POTENCIAL DE VENCEDOR]]) -> 8.7777778 | N41: =SUM(Form_Responses[[#This Row],[Adequação ao Tema]:[POTENCIAL DE VENCEDOR]]) -> 79
A42: 46291.348 | B42: Lennon | C42: 19. ORFEU | D42: 1 | E42: 7 | F42: 8 | G42: 10 | H42: 8 | I42: 10 | J42: 10 | K42: 10 | L42: 7 | M42: =AVERAGE(Form_Responses[[#This Row],[Adequação ao Tema]:[POTENCIAL DE VENCEDOR]]) -> 7.8888889 | N42: =SUM(Form_Responses[[#This Row],[Adequação ao Tema]:[POTENCIAL DE VENCEDOR]]) -> 71
A43: 46291.351 | B43: Lennon | C43: 21. Spear rush | D43: 10 | E43: 10 | F43: 8 | G43: 9 | H43: 8 | I43: 8 | J43: 10 | K43: 10 | L43: 8 | M43: =AVERAGE(Form_Responses[[#This Row],[Adequação ao Tema]:[POTENCIAL DE VENCEDOR]]) -> 9 | N43: =SUM(Form_Responses[[#This Row],[Adequação ao Tema]:[POTENCIAL DE VENCEDOR]]) -> 81
A44: 46291.353 | B44: Lennon | C44: 01. Block Busters | D44: 8 | E44: 10 | F44: 3 | G44: 10 | H44: 7 | I44: 5 | J44: 10 | K44: 8 | L44: 4 | M44: =AVERAGE(Form_Responses[[#This Row],[Adequação ao Tema]:[POTENCIAL DE VENCEDOR]]) -> 7.2222222 | N44: =SUM(Form_Responses[[#This Row],[Adequação ao Tema]:[POTENCIAL DE VENCEDOR]]) -> 65
A45: 46291.357 | B45: Lennon | C45: 04. Captus Gator | D45: 5 | E45: 7 | F45: 7 | G45: 10 | H45: 8 | I45: 8 | J45: 10 | K45: 10 | L45: 7 | M45: =AVERAGE(Form_Responses[[#This Row],[Adequação ao Tema]:[POTENCIAL DE VENCEDOR]]) -> 8 | N45: =SUM(Form_Responses[[#This Row],[Adequação ao Tema]:[POTENCIAL DE VENCEDOR]]) -> 72
A46: 46291.358 | B46: Lennon | C46: 05. Apenas Um Passo | D46: 8 | E46: 10 | F46: 5 | G46: 8 | H46: 8 | I46: 8 | J46: 10 | K46: 10 | L46: 7 | M46: =AVERAGE(Form_Responses[[#This Row],[Adequação ao Tema]:[POTENCIAL DE VENCEDOR]]) -> 8.2222222 | N46: =SUM(Form_Responses[[#This Row],[Adequação ao Tema]:[POTENCIAL DE VENCEDOR]]) -> 74
A47: 46291.36 | B47: Lennon | C47: 12. Singular | D47: 10 | E47: 10 | F47: 7 | G47: 8 | H47: 8 | I47: 8 | J47: 10 | K47: 10 | L47: 8 | M47: =AVERAGE(Form_Responses[[#This Row],[Adequação ao Tema]:[POTENCIAL DE VENCEDOR]]) -> 8.7777778 | N47: =SUM(Form_Responses[[#This Row],[Adequação ao Tema]:[POTENCIAL DE VENCEDOR]]) -> 79
A48: 46291.361 | B48: Lennon | C48: 18. Apenas um quarto | D48: 7 | E48: 7 | F48: 6 | G48: 10 | H48: 8 | I48: 7 | J48: 10 | K48: 10 | L48: 5 | M48: =AVERAGE(Form_Responses[[#This Row],[Adequação ao Tema]:[POTENCIAL DE VENCEDOR]]) -> 7.7777778 | N48: =SUM(Form_Responses[[#This Row],[Adequação ao Tema]:[POTENCIAL DE VENCEDOR]]) -> 70
A49: 46291.363 | B49: Lennon | C49: 20. O culpado entre nós | D49: 5 | E49: 5 | F49: 5 | G49: 10 | H49: 10 | I49: 7 | J49: 5 | K49: 10 | L49: 5 | M49: =AVERAGE(Form_Responses[[#This Row],[Adequação ao Tema]:[POTENCIAL DE VENCEDOR]]) -> 6.8888889 | N49: =SUM(Form_Responses[[#This Row],[Adequação ao Tema]:[POTENCIAL DE VENCEDOR]]) -> 62
A50: 46291.365 | B50: Lennon | C50: 22. Tiny Sword | D50: 5 | E50: 6 | F50: 7 | G50: 7 | H50: 8 | I50: 5 | J50: 6 | K50: 8 | L50: 5 | M50: =AVERAGE(Form_Responses[[#This Row],[Adequação ao Tema]:[POTENCIAL DE VENCEDOR]]) -> 6.3333333 | N50: =SUM(Form_Responses[[#This Row],[Adequação ao Tema]:[POTENCIAL DE VENCEDOR]]) -> 57
A51: 46291.39 | B51: Lennon | C51: 17. Paragominas: One Mission | D51: 9 | E51: 8 | F51: 7 | G51: 9 | H51: 10 | I51: 7 | J51: 10 | K51: 10 | L51: 8 | M51: =AVERAGE(Form_Responses[[#This Row],[Adequação ao Tema]:[POTENCIAL DE VENCEDOR]]) -> 8.6666667 | N51: =SUM(Form_Responses[[#This Row],[Adequação ao Tema]:[POTENCIAL DE VENCEDOR]]) -> 78
... A53: 46291.406 | B53: Lennon | C53: 03. Just One More Time | D53: 5 | E53: 7 | F53: 7 | G53: 8 | H53: 8 | I53: 7 | J53: 10 | K53: 10 | L53: 5 | M53: =AVERAGE(Form_Responses[[#This Row],[Adequação ao Tema]:[POTENCIAL DE VENCEDOR]]) -> 7.4444444 | N53: =SUM(Form_Responses[[#This Row],[Adequação ao Tema]:[POTENCIAL DE VENCEDOR]]) -> 67
A54: 46291.414 | B54: Manoel | C54: 11. The Apotheosis of Ivy | D54: 9 | E54: 8 | F54: 6 | G54: 7 | H54: 9 | I54: 9 | J54: 8 | K54: 9 | L54: 7 | M54: =AVERAGE(Form_Responses[[#This Row],[Adequação ao Tema]:[POTENCIAL DE VENCEDOR]]) -> 8 | N54: =SUM(Form_Responses[[#This Row],[Adequação ao Tema]:[POTENCIAL DE VENCEDOR]]) -> 72 | O54: Desafio interessante, percorrendo o percurso. Tem um enredo bom, apesar de ter um certo incentivo à violência.
A55: 46291.415 | B55: Manoel | C55: 15. Apenas um | D55: 3 | E55: 8 | F55: 4 | G55: 7 | H55: 5 | I55: 8 | J55: 3 | K55: 5 | L55: 2 | M55: =AVERAGE(Form_Responses[[#This Row],[Adequação ao Tema]:[POTENCIAL DE VENCEDOR]]) -> 5 | N55: =SUM(Form_Responses[[#This Row],[Adequação ao Tema]:[POTENCIAL DE VENCEDOR]]) -> 45 | O55: Bugs, personagens que não montam, dificuldade em compreender a dinâmica, demora entre execuções.
A56: 46291.417 | B56: Manoel | C56: 16. One Slay | D56: 6 | E56: 6 | F56: 3 | G56: 6 | H56: 5 | I56: 6 | J56: 4 | K56: 3 | L56: 1 | M56: =AVERAGE(Form_Responses[[#This Row],[Adequação ao Tema]:[POTENCIAL DE VENCEDOR]]) -> 4.4444444 | N56: =SUM(Form_Responses[[#This Row],[Adequação ao Tema]:[POTENCIAL DE VENCEDOR]]) -> 40 | O56: Regras não muito bem especificadas, comandos que não funcionam, um pouco distante da proposta.

Sheet Tabela

Sheet Pontuação
B1: NIVEL | C1: EQUIPE | D1: SOMA | E1: APRESENTAÇÃO | F1: NOTA
C2: ='Respostas ao formulário 1'!C2 -> 01. Block Busters | D2: =SUM('Respostas ao formulário 1'!D2:L2) -> 78 | E2: 10
C3: ='Respostas ao formulário 1'!C3 -> 02. Apenas Uma Porta | D3: =SUM('Respostas ao formulário 1'!D3:L3) -> 70 | E3: 10
C4: ='Respostas ao formulário 1'!C4 -> 03. Just One More Time | D4: =SUM('Respostas ao formulário 1'!D4:L4) -> 74 | E4: 10
C5: ='Respostas ao formulário 1'!C5 -> 04. Captus Gator | D5: =SUM('Respostas ao formulário 1'!D5:L5) -> 77 | E5: 10
C6: ='Respostas ao formulário 1'!C6 -> 05. Apenas Um Passo | D6: =SUM('Respostas ao formulário 1'!D6:L6) -> 77 | E6: 10
C7: ='Respostas ao formulário 1'!C7 -> 06. O último clique | D7: =SUM('Respostas ao formulário 1'!D7:L7) -> 61 | E7: 10
C8: ='Respostas ao formulário 1'!C8 -> 07. Apenas uma luz | D8: =SUM('Respostas ao formulário 1'!D8:L8) -> 68 | E8: 10
B9: SUPERIOR | C9: ='Respostas ao formulário 1'!C9 -> 08. BLACK FOREST | D9: =SUM('Respostas ao formulário 1'!D9:L9) -> 70 | E9: 10
C10: ='Respostas ao formulário 1'!C10 -> 09. RESTA UM | D10: =SUM('Respostas ao formulário 1'!D10:L10) -> 64 | E10: 10
C11: ='Respostas ao formulário 1'!C11 -> 10. A ÚLTIMA CHANCE | D11: =SUM('Respostas ao formulário 1'!D11:L11) -> 73 | E11: 10
C12: ='Respostas ao formulário 1'!C12 -> 11. The Apotheosis of Ivy | D12: =SUM('Respostas ao formulário 1'!D12:L12) -> 69 | E12: 10
C13: ='Respostas ao formulário 1'!C13 -> 12. Singular | D13: =SUM('Respostas ao formulário 1'!D13:L13) -> 79 | E13: 10
C14: ='Respostas ao formulário 1'!C14 -> 13. Apenas um Erro Matemático | D14: =SUM('Respostas ao formulário 1'!D14:L14) -> 70 | E14: 10
B15: SUPERIOR | C15: ='Respostas ao formulário 1'!C15 -> 14. INFragmentado | D15: =SUM('Respostas ao formulário 1'!D15:L15) -> 75 | E15: 10
C16: ='Respostas ao formulário 1'!C16 -> 16. One Slay | D16: =SUM('Respostas ao formulário 1'!D16:L16) -> 55 | E16: 10
B17: SUPERIOR | C17: ='Respostas ao formulário 1'!C17 -> 17. Paragominas: One Mission | D17: =SUM('Respostas ao formulário 1'!D17:L17) -> 77 | E17: 10
C18: ='Respostas ao formulário 1'!C18 -> 18. Apenas um quarto | D18: =SUM('Respostas ao formulário 1'!D18:L18) -> 67 | E18: 10
B19: SUPERIOR | C19: ='Respostas ao formulário 1'!C19 -> 19. ORFEU | D19: =SUM('Respostas ao formulário 1'!D19:L19) -> 79 | E19: 10
C20: ='Respostas ao formulário 1'!C20 -> 20. O culpado entre nós | D20: =SUM('Respostas ao formulário 1'!D20:L20) -> 80 | E20: 10
B21: SUPERIOR | C21: ='Respostas ao formulário 1'!C21 -> 21. Spear rush | D21: =SUM('Respostas ao formulário 1'!D21:L21) -> 83 | E21: 10
C22: ='Respostas ao formulário 1'!C22 -> 22. Tiny Sword | D22: =SUM('Respostas ao formulário 1'!D22:L22) -> 68 | E22: 10
C23: ='Respostas ao formulário 1'!C23 -> 08. BLACK FOREST | D23: =SUM('Respostas ao formulário 1'!D23:L23) -> 66 | E23: 10
C24: ='Respostas ao formulário 1'!C24 -> 14. INFragmentado | D24: =SUM('Respostas ao formulário 1'!D24:L24) -> 61 | E24: 10
C25: ='Respostas ao formulário 1'!C25 -> 17. Paragominas: One Mission | D25: =SUM('Respostas ao formulário 1'!D25:L25) -> 88 | E25: 10
C26: ='Respostas ao formulário 1'!C26 -> 19. ORFEU | D26: =SUM('Respostas ao formulário 1'!D26:L26) -> 66 | E26: 10
C27: ='Respostas ao formulário 1'!C27 -> 21. Spear rush | D27: =SUM('Respostas ao formulário 1'!D27:L27) -> 81 | E27: 10
C28: ='Respostas ao formulário 1'!C28 -> 01. Block Busters | D28: =SUM('Respostas ao formulário 1'!D28:L28) -> 81 | E28: 10
C29: ='Respostas ao formulário 1'!C29 -> 04. Captus Gator | D29: =SUM('Respostas ao formulário 1'!D29:L29) -> 75 | E29: 10
C30: ='Respostas ao formulário 1'!C30 -> 02. Apenas Uma Porta | D30: =SUM('Respostas ao formulário 1'!D30:L30) -> 70 | E30: 10
C31: ='Respostas ao formulário 1'!C31 -> 05. Apenas Um Passo | D31: =SUM('Respostas ao formulário 1'!D31:L31) -> 38 | E31: 10
C32: ='Respostas ao formulário 1'!C32 -> 07. Apenas uma luz | D32: =SUM('Respostas ao formulário 1'!D32:L32) -> 65 | E32: 10
C33: ='Respostas ao formulário 1'!C33 -> 09. RESTA UM | D33: =SUM('Respostas ao formulário 1'!D33:L33) -> 41 | E33: 10
... C41: ='Respostas ao formulário 1'!C41 -> 14. INFragmentado | D41: =SUM('Respostas ao formulário 1'!D41:L41) -> 79 | E41: 10
C42: ='Respostas ao formulário 1'!#REF! -> #REF! | D42: =SUM('Respostas ao formulário 1'!#REF!) -> #REF! | E42: 10
C43: ='Respostas ao formulário 1'!C42 -> 19. ORFEU | D43: =SUM('Respostas ao formulário 1'!D42:L42) -> 71 | E43: 10
C44: ='Respostas ao formulário 1'!C43 -> 21. Spear rush | D44: =SUM('Respostas ao formulário 1'!D43:L43) -> 81 | E44: 10
C45: ='Respostas ao formulário 1'!C44 -> 01. Block Busters | D45: =SUM('Respostas ao formulário 1'!D44:L44) -> 65 | E45: 10
C46: ='Respostas ao formulário 1'!C45 -> 04. Captus Gator | D46: =SUM('Respostas ao formulário 1'!D45:L45) -> 72 | E46: 10
C47: ='Respostas ao formulário 1'!C46 -> 05. Apenas Um Passo | D47: =SUM('Respostas ao formulário 1'!D46:L46) -> 74 | E47: 10
...
